<?xml version="1.0" ?>
<!-- =================================================================================== -->
<!-- |    This document was autogenerated by xacro from yannic_robot.urdf.xacro        | -->
<!-- |    EDITING THIS FILE BY HAND IS NOT RECOMMENDED                                 | -->
<!-- =================================================================================== -->
<robot name="yannic_robot">
  <material name="blue">
    <color rgba="0 0 0.8 1"/>
  </material>
  <material name="transparent">
    <color rgba="0 0 0 0"/>
  </material>
  <material name="green">
    <color rgba="0.0 0.8 0.0 1.0"/>
  </material>
  <material name="white">
    <color rgba="1 1 1 1"/>
  </material>
  <link name="base_link">
    <visual>
      <geometry>
        <box size="0.05 0.001  0.01"/>
      </geometry>
      <material name="blue"/>
    </visual>
    <collision>
      <geometry>
        <box size="0.05 0.001  0.01"/>
      </geometry>
    </collision>
  </link>
  <joint name="rotate_base" type="revolute">
    <axis xyz="1 0 0"/>
    <limit effort="1000.0" lower="-1.57" upper="1.57" velocity="0.5"/>
    <origin rpy="0 0 1.57" xyz="0.0005 0 0"/>
    <parent link="base_link"/>
    <child link="dummy"/>
  </joint>
  <link name="dummy">
    <visual>
      <geometry>
        <box size="0.013 0.001  0.01"/>
      </geometry>
      <material name="white"/>
      <origin rpy="0 0 0" xyz="0.0065 0 0.0"/>
    </visual>
    <collision>
      <geometry>
        <box size="0.013 0.001  0.01"/>
      </geometry>
    </collision>
    <inertial>
      <mass value="10"/>
      <inertia ixx="1.0" ixy="0.0" ixz="0.0" iyy="1.0" iyz="0.0" izz="1.0"/>
    </inertial>
  </link>
  <joint name="joint1" type="revolute">
    <axis xyz="0 0 1"/>
    <limit effort="1000.0" lower="-0.7853981633974483" upper="0.7853981633974483" velocity="0.5"/>
    <origin rpy="0 0 0" xyz="0.013 0 0"/>
    <parent link="dummy"/>
    <child link="link1"/>
  </joint>
  <link name="link1">
    <visual>
      <geometry>
        <box size="0.182 0.001  0.01"/>
      </geometry>
      <material name="blue"/>
      <origin rpy="0 0 0" xyz="0.091 0 0.0"/>
    </visual>
    <collision>
      <geometry>
        <box size="0.182 0.001  0.01"/>
      </geometry>
    </collision>
    <inertial>
      <mass value="10"/>
      <inertia ixx="1.0" ixy="0.0" ixz="0.0" iyy="1.0" iyz="0.0" izz="1.0"/>
    </inertial>
  </link>
  <joint name="joint2" type="revolute">
    <axis xyz="0 0 1"/>
    <limit effort="1000.0" lower="0.7853981633974483" upper="2.356194490192345" velocity="0.5"/>
    <origin rpy="0 0 0" xyz="0.182 0 0"/>
    <parent link="link1"/>
    <child link="link2"/>
  </joint>
  <link name="link2">
    <visual>
      <geometry>
        <box size="0.125 0.001  0.01"/>
      </geometry>
      <material name="green"/>
      <origin rpy="0 0 0" xyz="0.0625 0 0.0"/>
    </visual>
    <collision>
      <geometry>
        <box size="0.125 0.001  0.01"/>
      </geometry>
    </collision>
    <inertial>
      <mass value="10"/>
      <inertia ixx="1.0" ixy="0.0" ixz="0.0" iyy="1.0" iyz="0.0" izz="1.0"/>
    </inertial>
  </link>
  <joint name="joint3" type="revolute">
    <axis xyz="0 0 1"/>
    <limit effort="1000.0" lower="-1.5707963267948966" upper="1.5707963267948966" velocity="0.5"/>
    <origin rpy="0 0 0" xyz="0.125 0 0"/>
    <parent link="link2"/>
    <child link="link3"/>
  </joint>
  <link name="link3">
    <visual>
      <geometry>
        <box size="0.054 0.001  0.01"/>
      </geometry>
      <material name="blue"/>
      <origin rpy="0 0 0" xyz="0.027 0 0.0"/>
    </visual>
    <collision>
      <geometry>
        <box size="0.054 0.001  0.01"/>
      </geometry>
    </collision>
    <inertial>
      <mass value="10"/>
      <inertia ixx="1.0" ixy="0.0" ixz="0.0" iyy="1.0" iyz="0.0" izz="1.0"/>
    </inertial>
  </link>
  <joint name="gripper_joint" type="prismatic">
    <axis xyz="0 1 0"/>
    <limit effort="1000.0" lower="0" upper="0.03" velocity="0.5"/>
    <origin rpy="1.5707963267948966 0 0" xyz="0.054 0 0"/>
    <parent link="link3"/>
    <child link="gripper"/>
  </joint>
  <link name="gripper">
    <visual>
      <geometry>
        <box size="0.03 0.001  0.01"/>
      </geometry>
      <origin rpy="0 0 0" xyz="0.015 0 0"/>
      <material name="green"/>
    </visual>
    <collision>
      <geometry>
        <box size="0.03 0.001  0.01"/>
      </geometry>
    </collision>
    <inertial>
      <mass value="0.5"/>
      <inertia ixx="1.0" ixy="0.0" ixz="0.0" iyy="1.0" iyz="0.0" izz="1.0"/>
    </inertial>
  </link>
  <joint name="left_gripper" type="prismatic">
    <axis xyz="0 1 0"/>
    <limit effort="1000.0" lower="0" upper="0.03" velocity="0.5"/>
    <origin rpy="-1.5707963267948966 0 0" xyz="0.054 0 0"/>
    <parent link="link3"/>
    <child link="left_gripper"/>
    <mimic joint="gripper_joint" multiplier="1" offset="0"/>
  </joint>
  <link name="left_gripper">
    <visual>
      <geometry>
        <box size="0.03 0.001  0.01"/>
      </geometry>
      <origin rpy="0 0 0" xyz="0.015 0 0"/>
      <material name="green"/>
    </visual>
    <collision>
      <geometry>
        <box size="0.03 0.001  0.01"/>
      </geometry>
    </collision>
    <inertial>
      <mass value="0.5"/>
      <inertia ixx="1.0" ixy="0.0" ixz="0.0" iyy="1.0" iyz="0.0" izz="1.0"/>
    </inertial>
  </link>
  <joint name="endeff_joint" type="fixed">
    <origin rpy="0 0 0" xyz="0.054 0 0"/>
    <parent link="link3"/>
    <child link="endeff"/>
  </joint>
  <link name="endeff">
    <visual>
      <geometry>
        <box size="0.0001 0.001  0.01"/>
      </geometry>
      <material name="transparent"/>
      <origin rpy="0 0 0" xyz="5e-05 0 0.0"/>
    </visual>
    <collision>
      <geometry>
        <box size="0.0001 0.001  0.01"/>
      </geometry>
    </collision>
    <inertial>
      <mass value="0.01"/>
      <inertia ixx="1.0" ixy="0.0" ixz="0.0" iyy="1.0" iyz="0.0" izz="1.0"/>
    </inertial>
  </link>
</robot>
